[2022-10-29 16:27:45,231] {taskinstance.py:1179} INFO - Dependencies all met for <TaskInstance: get_files_denue.extract scheduled__2022-09-01T00:00:00+00:00 [queued]>
[2022-10-29 16:27:45,236] {taskinstance.py:1179} INFO - Dependencies all met for <TaskInstance: get_files_denue.extract scheduled__2022-09-01T00:00:00+00:00 [queued]>
[2022-10-29 16:27:45,236] {taskinstance.py:1376} INFO - 
--------------------------------------------------------------------------------
[2022-10-29 16:27:45,236] {taskinstance.py:1377} INFO - Starting attempt 3 of 8
[2022-10-29 16:27:45,236] {taskinstance.py:1378} INFO - 
--------------------------------------------------------------------------------
[2022-10-29 16:27:45,244] {taskinstance.py:1397} INFO - Executing <Task(_PythonDecoratedOperator): extract> on 2022-09-01 00:00:00+00:00
[2022-10-29 16:27:45,248] {standard_task_runner.py:52} INFO - Started process 506 to run task
[2022-10-29 16:27:45,250] {standard_task_runner.py:79} INFO - Running: ['***', 'tasks', 'run', 'get_files_denue', 'extract', 'scheduled__2022-09-01T00:00:00+00:00', '--job-id', '5', '--raw', '--subdir', 'DAGS_FOLDER/get_raw_files/get_files_denue.py', '--cfg-path', '/tmp/tmpajk1706u', '--error-file', '/tmp/tmpcuf_5oip']
[2022-10-29 16:27:45,251] {standard_task_runner.py:80} INFO - Job 5: Subtask extract
[2022-10-29 16:27:45,374] {task_command.py:371} INFO - Running <TaskInstance: get_files_denue.extract scheduled__2022-09-01T00:00:00+00:00 [running]> on host 0e9bebf0afc5
[2022-10-29 16:27:45,414] {taskinstance.py:1591} INFO - Exporting the following env vars:
AIRFLOW_CTX_DAG_OWNER=Freakisimo
AIRFLOW_CTX_DAG_ID=get_files_denue
AIRFLOW_CTX_TASK_ID=extract
AIRFLOW_CTX_EXECUTION_DATE=2022-09-01T00:00:00+00:00
AIRFLOW_CTX_TRY_NUMBER=3
AIRFLOW_CTX_DAG_RUN_ID=scheduled__2022-09-01T00:00:00+00:00
[2022-10-29 16:27:45,415] {taskinstance.py:1909} ERROR - Task failed with exception
Traceback (most recent call last):
  File "/home/airflow/.local/lib/python3.7/site-packages/airflow/decorators/base.py", line 179, in execute
    return_value = super().execute(context)
  File "/home/airflow/.local/lib/python3.7/site-packages/airflow/operators/python.py", line 171, in execute
    return_value = self.execute_callable()
  File "/home/airflow/.local/lib/python3.7/site-packages/airflow/operators/python.py", line 189, in execute_callable
    return self.python_callable(*self.op_args, **self.op_kwargs)
  File "/opt/airflow/dags/get_raw_files/get_files_denue.py", line 28, in extract
    innertext='en formato csv'
  File "/opt/airflow/dags/utils/python_tools.py", line 35, in download_files
    os.chmod('/chromedriver/chromedriver', 0o755)
PermissionError: [Errno 1] Operation not permitted: '/chromedriver/chromedriver'
[2022-10-29 16:27:45,419] {taskinstance.py:1420} INFO - Marking task as UP_FOR_RETRY. dag_id=get_files_denue, task_id=extract, execution_date=20220901T000000, start_date=20221029T162745, end_date=20221029T162745
[2022-10-29 16:27:45,425] {standard_task_runner.py:97} ERROR - Failed to execute job 5 for task extract ([Errno 1] Operation not permitted: '/chromedriver/chromedriver'; 506)
[2022-10-29 16:27:45,461] {local_task_job.py:156} INFO - Task exited with return code 1
[2022-10-29 16:27:45,574] {local_task_job.py:273} INFO - 0 downstream tasks scheduled from follow-on schedule check
[2022-10-29 16:38:36,215] {taskinstance.py:1179} INFO - Dependencies all met for <TaskInstance: get_files_denue.extract scheduled__2022-09-01T00:00:00+00:00 [queued]>
[2022-10-29 16:38:36,220] {taskinstance.py:1179} INFO - Dependencies all met for <TaskInstance: get_files_denue.extract scheduled__2022-09-01T00:00:00+00:00 [queued]>
[2022-10-29 16:38:36,220] {taskinstance.py:1376} INFO - 
--------------------------------------------------------------------------------
[2022-10-29 16:38:36,221] {taskinstance.py:1377} INFO - Starting attempt 3 of 7
[2022-10-29 16:38:36,221] {taskinstance.py:1378} INFO - 
--------------------------------------------------------------------------------
[2022-10-29 16:38:36,228] {taskinstance.py:1397} INFO - Executing <Task(_PythonDecoratedOperator): extract> on 2022-09-01 00:00:00+00:00
[2022-10-29 16:38:36,234] {standard_task_runner.py:52} INFO - Started process 714 to run task
[2022-10-29 16:38:36,235] {standard_task_runner.py:79} INFO - Running: ['***', 'tasks', 'run', 'get_files_denue', 'extract', 'scheduled__2022-09-01T00:00:00+00:00', '--job-id', '5', '--raw', '--subdir', 'DAGS_FOLDER/get_raw_files/get_files_denue.py', '--cfg-path', '/tmp/tmpm0ty2a_s', '--error-file', '/tmp/tmpze5pwvmv']
[2022-10-29 16:38:36,236] {standard_task_runner.py:80} INFO - Job 5: Subtask extract
[2022-10-29 16:38:36,363] {task_command.py:371} INFO - Running <TaskInstance: get_files_denue.extract scheduled__2022-09-01T00:00:00+00:00 [running]> on host 5e8bab7a3cdc
[2022-10-29 16:38:36,403] {taskinstance.py:1591} INFO - Exporting the following env vars:
AIRFLOW_CTX_DAG_OWNER=Freakisimo
AIRFLOW_CTX_DAG_ID=get_files_denue
AIRFLOW_CTX_TASK_ID=extract
AIRFLOW_CTX_EXECUTION_DATE=2022-09-01T00:00:00+00:00
AIRFLOW_CTX_TRY_NUMBER=3
AIRFLOW_CTX_DAG_RUN_ID=scheduled__2022-09-01T00:00:00+00:00
[2022-10-29 16:38:36,412] {taskinstance.py:1909} ERROR - Task failed with exception
Traceback (most recent call last):
  File "/home/airflow/.local/lib/python3.7/site-packages/selenium/webdriver/common/service.py", line 76, in start
    creationflags=self.creationflags)
  File "/usr/local/lib/python3.7/subprocess.py", line 800, in __init__
    restore_signals, start_new_session)
  File "/usr/local/lib/python3.7/subprocess.py", line 1551, in _execute_child
    raise child_exception_type(errno_num, err_msg, err_filename)
PermissionError: [Errno 13] Permission denied: '/chromedriver/chromedriver'

During handling of the above exception, another exception occurred:

Traceback (most recent call last):
  File "/home/airflow/.local/lib/python3.7/site-packages/airflow/decorators/base.py", line 179, in execute
    return_value = super().execute(context)
  File "/home/airflow/.local/lib/python3.7/site-packages/airflow/operators/python.py", line 171, in execute
    return_value = self.execute_callable()
  File "/home/airflow/.local/lib/python3.7/site-packages/airflow/operators/python.py", line 189, in execute_callable
    return self.python_callable(*self.op_args, **self.op_kwargs)
  File "/opt/airflow/dags/get_raw_files/get_files_denue.py", line 28, in extract
    innertext='en formato csv'
  File "/opt/airflow/dags/utils/python_tools.py", line 35, in download_files
    driver = webdriver.Chrome(executable_path='/chromedriver/chromedriver')
  File "/home/airflow/.local/lib/python3.7/site-packages/selenium/webdriver/chrome/webdriver.py", line 72, in __init__
    service_log_path, service, keep_alive)
  File "/home/airflow/.local/lib/python3.7/site-packages/selenium/webdriver/chromium/webdriver.py", line 89, in __init__
    self.service.start()
  File "/home/airflow/.local/lib/python3.7/site-packages/selenium/webdriver/common/service.py", line 88, in start
    os.path.basename(self.path), self.start_error_message)
selenium.common.exceptions.WebDriverException: Message: 'chromedriver' executable may have wrong permissions. Please see https://chromedriver.chromium.org/home

[2022-10-29 16:38:36,418] {taskinstance.py:1420} INFO - Marking task as UP_FOR_RETRY. dag_id=get_files_denue, task_id=extract, execution_date=20220901T000000, start_date=20221029T163836, end_date=20221029T163836
[2022-10-29 16:38:36,424] {standard_task_runner.py:97} ERROR - Failed to execute job 5 for task extract (Message: 'chromedriver' executable may have wrong permissions. Please see https://chromedriver.chromium.org/home
; 714)
[2022-10-29 16:38:36,447] {local_task_job.py:156} INFO - Task exited with return code 1
[2022-10-29 16:38:36,558] {local_task_job.py:273} INFO - 0 downstream tasks scheduled from follow-on schedule check
[2022-10-29 17:04:41,985] {taskinstance.py:1179} INFO - Dependencies all met for <TaskInstance: get_files_denue.extract scheduled__2022-09-01T00:00:00+00:00 [queued]>
[2022-10-29 17:04:41,990] {taskinstance.py:1179} INFO - Dependencies all met for <TaskInstance: get_files_denue.extract scheduled__2022-09-01T00:00:00+00:00 [queued]>
[2022-10-29 17:04:41,990] {taskinstance.py:1376} INFO - 
--------------------------------------------------------------------------------
[2022-10-29 17:04:41,990] {taskinstance.py:1377} INFO - Starting attempt 3 of 6
[2022-10-29 17:04:41,990] {taskinstance.py:1378} INFO - 
--------------------------------------------------------------------------------
[2022-10-29 17:04:41,998] {taskinstance.py:1397} INFO - Executing <Task(_PythonDecoratedOperator): extract> on 2022-09-01 00:00:00+00:00
[2022-10-29 17:04:42,003] {standard_task_runner.py:52} INFO - Started process 949 to run task
[2022-10-29 17:04:42,005] {standard_task_runner.py:79} INFO - Running: ['***', 'tasks', 'run', 'get_files_denue', 'extract', 'scheduled__2022-09-01T00:00:00+00:00', '--job-id', '5', '--raw', '--subdir', 'DAGS_FOLDER/get_raw_files/get_files_denue.py', '--cfg-path', '/tmp/tmpr1_i8yzu', '--error-file', '/tmp/tmpwrxpdodn']
[2022-10-29 17:04:42,005] {standard_task_runner.py:80} INFO - Job 5: Subtask extract
[2022-10-29 17:04:42,132] {task_command.py:371} INFO - Running <TaskInstance: get_files_denue.extract scheduled__2022-09-01T00:00:00+00:00 [running]> on host 167153ec7ac7
[2022-10-29 17:04:42,172] {taskinstance.py:1591} INFO - Exporting the following env vars:
AIRFLOW_CTX_DAG_OWNER=Freakisimo
AIRFLOW_CTX_DAG_ID=get_files_denue
AIRFLOW_CTX_TASK_ID=extract
AIRFLOW_CTX_EXECUTION_DATE=2022-09-01T00:00:00+00:00
AIRFLOW_CTX_TRY_NUMBER=3
AIRFLOW_CTX_DAG_RUN_ID=scheduled__2022-09-01T00:00:00+00:00
[2022-10-29 17:04:42,181] {taskinstance.py:1909} ERROR - Task failed with exception
Traceback (most recent call last):
  File "/home/airflow/.local/lib/python3.7/site-packages/selenium/webdriver/common/service.py", line 76, in start
    creationflags=self.creationflags)
  File "/usr/local/lib/python3.7/subprocess.py", line 800, in __init__
    restore_signals, start_new_session)
  File "/usr/local/lib/python3.7/subprocess.py", line 1551, in _execute_child
    raise child_exception_type(errno_num, err_msg, err_filename)
PermissionError: [Errno 13] Permission denied: '/chromedriver/chromedriver'

During handling of the above exception, another exception occurred:

Traceback (most recent call last):
  File "/home/airflow/.local/lib/python3.7/site-packages/airflow/decorators/base.py", line 179, in execute
    return_value = super().execute(context)
  File "/home/airflow/.local/lib/python3.7/site-packages/airflow/operators/python.py", line 171, in execute
    return_value = self.execute_callable()
  File "/home/airflow/.local/lib/python3.7/site-packages/airflow/operators/python.py", line 189, in execute_callable
    return self.python_callable(*self.op_args, **self.op_kwargs)
  File "/opt/airflow/dags/get_raw_files/get_files_denue.py", line 28, in extract
    innertext='en formato csv'
  File "/opt/airflow/dags/utils/python_tools.py", line 39, in download_files
    driver = webdriver.Chrome(executable_path='/chromedriver/chromedriver', options=chrome_options)
  File "/home/airflow/.local/lib/python3.7/site-packages/selenium/webdriver/chrome/webdriver.py", line 72, in __init__
    service_log_path, service, keep_alive)
  File "/home/airflow/.local/lib/python3.7/site-packages/selenium/webdriver/chromium/webdriver.py", line 89, in __init__
    self.service.start()
  File "/home/airflow/.local/lib/python3.7/site-packages/selenium/webdriver/common/service.py", line 88, in start
    os.path.basename(self.path), self.start_error_message)
selenium.common.exceptions.WebDriverException: Message: 'chromedriver' executable may have wrong permissions. Please see https://chromedriver.chromium.org/home

[2022-10-29 17:04:42,186] {taskinstance.py:1420} INFO - Marking task as UP_FOR_RETRY. dag_id=get_files_denue, task_id=extract, execution_date=20220901T000000, start_date=20221029T170441, end_date=20221029T170442
[2022-10-29 17:04:42,192] {standard_task_runner.py:97} ERROR - Failed to execute job 5 for task extract (Message: 'chromedriver' executable may have wrong permissions. Please see https://chromedriver.chromium.org/home
; 949)
[2022-10-29 17:04:42,216] {local_task_job.py:156} INFO - Task exited with return code 1
[2022-10-29 17:04:42,327] {local_task_job.py:273} INFO - 0 downstream tasks scheduled from follow-on schedule check
