[2022-10-28 21:47:28,811] {taskinstance.py:1179} INFO - Dependencies all met for <TaskInstance: get_files_denue.extract scheduled__2022-09-01T00:00:00+00:00 [queued]>
[2022-10-28 21:47:28,817] {taskinstance.py:1179} INFO - Dependencies all met for <TaskInstance: get_files_denue.extract scheduled__2022-09-01T00:00:00+00:00 [queued]>
[2022-10-28 21:47:28,817] {taskinstance.py:1376} INFO - 
--------------------------------------------------------------------------------
[2022-10-28 21:47:28,817] {taskinstance.py:1377} INFO - Starting attempt 1 of 6
[2022-10-28 21:47:28,817] {taskinstance.py:1378} INFO - 
--------------------------------------------------------------------------------
[2022-10-28 21:47:28,825] {taskinstance.py:1397} INFO - Executing <Task(_PythonDecoratedOperator): extract> on 2022-09-01 00:00:00+00:00
[2022-10-28 21:47:28,830] {standard_task_runner.py:52} INFO - Started process 206 to run task
[2022-10-28 21:47:28,831] {standard_task_runner.py:79} INFO - Running: ['***', 'tasks', 'run', 'get_files_denue', 'extract', 'scheduled__2022-09-01T00:00:00+00:00', '--job-id', '3', '--raw', '--subdir', 'DAGS_FOLDER/get_raw_files/get_files_denue.py', '--cfg-path', '/tmp/tmpco9j8dal', '--error-file', '/tmp/tmpng2waatg']
[2022-10-28 21:47:28,832] {standard_task_runner.py:80} INFO - Job 3: Subtask extract
[2022-10-28 21:47:28,864] {task_command.py:371} INFO - Running <TaskInstance: get_files_denue.extract scheduled__2022-09-01T00:00:00+00:00 [running]> on host bb2b8b2f7954
[2022-10-28 21:47:29,003] {taskinstance.py:1591} INFO - Exporting the following env vars:
AIRFLOW_CTX_DAG_OWNER=Freakisimo
AIRFLOW_CTX_DAG_ID=get_files_denue
AIRFLOW_CTX_TASK_ID=extract
AIRFLOW_CTX_EXECUTION_DATE=2022-09-01T00:00:00+00:00
AIRFLOW_CTX_TRY_NUMBER=1
AIRFLOW_CTX_DAG_RUN_ID=scheduled__2022-09-01T00:00:00+00:00
[2022-10-28 21:47:29,370] {python.py:173} INFO - Done. Returned value was: []
[2022-10-28 21:47:29,386] {taskinstance.py:1420} INFO - Marking task as SUCCESS. dag_id=get_files_denue, task_id=extract, execution_date=20220901T000000, start_date=20221028T214728, end_date=20221028T214729
[2022-10-28 21:47:29,403] {local_task_job.py:156} INFO - Task exited with return code 0
[2022-10-28 21:47:29,429] {local_task_job.py:273} INFO - 1 downstream tasks scheduled from follow-on schedule check
[2022-10-29 02:21:29,583] {taskinstance.py:1179} INFO - Dependencies all met for <TaskInstance: get_files_denue.extract scheduled__2022-09-01T00:00:00+00:00 [queued]>
[2022-10-29 02:21:29,588] {taskinstance.py:1179} INFO - Dependencies all met for <TaskInstance: get_files_denue.extract scheduled__2022-09-01T00:00:00+00:00 [queued]>
[2022-10-29 02:21:29,588] {taskinstance.py:1376} INFO - 
--------------------------------------------------------------------------------
[2022-10-29 02:21:29,588] {taskinstance.py:1377} INFO - Starting attempt 1 of 6
[2022-10-29 02:21:29,588] {taskinstance.py:1378} INFO - 
--------------------------------------------------------------------------------
[2022-10-29 02:21:29,596] {taskinstance.py:1397} INFO - Executing <Task(_PythonDecoratedOperator): extract> on 2022-09-01 00:00:00+00:00
[2022-10-29 02:21:29,600] {standard_task_runner.py:52} INFO - Started process 206 to run task
[2022-10-29 02:21:29,602] {standard_task_runner.py:79} INFO - Running: ['***', 'tasks', 'run', 'get_files_denue', 'extract', 'scheduled__2022-09-01T00:00:00+00:00', '--job-id', '3', '--raw', '--subdir', 'DAGS_FOLDER/get_raw_files/get_files_denue.py', '--cfg-path', '/tmp/tmpdtdey7gm', '--error-file', '/tmp/tmp9kq6_6f7']
[2022-10-29 02:21:29,603] {standard_task_runner.py:80} INFO - Job 3: Subtask extract
[2022-10-29 02:21:29,730] {task_command.py:371} INFO - Running <TaskInstance: get_files_denue.extract scheduled__2022-09-01T00:00:00+00:00 [running]> on host f7ba62d7d52e
[2022-10-29 02:21:29,775] {taskinstance.py:1591} INFO - Exporting the following env vars:
AIRFLOW_CTX_DAG_OWNER=Freakisimo
AIRFLOW_CTX_DAG_ID=get_files_denue
AIRFLOW_CTX_TASK_ID=extract
AIRFLOW_CTX_EXECUTION_DATE=2022-09-01T00:00:00+00:00
AIRFLOW_CTX_TRY_NUMBER=1
AIRFLOW_CTX_DAG_RUN_ID=scheduled__2022-09-01T00:00:00+00:00
[2022-10-29 02:21:30,284] {taskinstance.py:1909} ERROR - Task failed with exception
Traceback (most recent call last):
  File "/home/airflow/.local/lib/python3.7/site-packages/airflow/decorators/base.py", line 179, in execute
    return_value = super().execute(context)
  File "/home/airflow/.local/lib/python3.7/site-packages/airflow/operators/python.py", line 171, in execute
    return_value = self.execute_callable()
  File "/home/airflow/.local/lib/python3.7/site-packages/airflow/operators/python.py", line 189, in execute_callable
    return self.python_callable(*self.op_args, **self.op_kwargs)
  File "/opt/airflow/dags/get_raw_files/get_files_denue.py", line 28, in extract
    innertext='en formato csv'
  File "/opt/airflow/dags/utils/python_tools.py", line 35, in download_files
    driver = webdriver.Chrome()
  File "/home/airflow/.local/lib/python3.7/site-packages/selenium/webdriver/chrome/webdriver.py", line 72, in __init__
    service_log_path, service, keep_alive)
  File "/home/airflow/.local/lib/python3.7/site-packages/selenium/webdriver/chromium/webdriver.py", line 89, in __init__
    self.service.start()
  File "/home/airflow/.local/lib/python3.7/site-packages/selenium/webdriver/common/service.py", line 98, in start
    self.assert_process_still_running()
  File "/home/airflow/.local/lib/python3.7/site-packages/selenium/webdriver/common/service.py", line 112, in assert_process_still_running
    % (self.path, return_code)
selenium.common.exceptions.WebDriverException: Message: Service chromedriver unexpectedly exited. Status code was: 127

[2022-10-29 02:21:30,291] {taskinstance.py:1420} INFO - Marking task as UP_FOR_RETRY. dag_id=get_files_denue, task_id=extract, execution_date=20220901T000000, start_date=20221029T022129, end_date=20221029T022130
[2022-10-29 02:21:30,299] {standard_task_runner.py:97} ERROR - Failed to execute job 3 for task extract (Message: Service chromedriver unexpectedly exited. Status code was: 127
; 206)
[2022-10-29 02:21:30,334] {local_task_job.py:156} INFO - Task exited with return code 1
[2022-10-29 02:21:30,453] {local_task_job.py:273} INFO - 0 downstream tasks scheduled from follow-on schedule check
[2022-10-29 16:00:44,930] {taskinstance.py:1179} INFO - Dependencies all met for <TaskInstance: get_files_denue.extract scheduled__2022-09-01T00:00:00+00:00 [queued]>
[2022-10-29 16:00:44,935] {taskinstance.py:1179} INFO - Dependencies all met for <TaskInstance: get_files_denue.extract scheduled__2022-09-01T00:00:00+00:00 [queued]>
[2022-10-29 16:00:44,936] {taskinstance.py:1376} INFO - 
--------------------------------------------------------------------------------
[2022-10-29 16:00:44,936] {taskinstance.py:1377} INFO - Starting attempt 1 of 6
[2022-10-29 16:00:44,936] {taskinstance.py:1378} INFO - 
--------------------------------------------------------------------------------
[2022-10-29 16:00:44,943] {taskinstance.py:1397} INFO - Executing <Task(_PythonDecoratedOperator): extract> on 2022-09-01 00:00:00+00:00
[2022-10-29 16:00:44,947] {standard_task_runner.py:52} INFO - Started process 206 to run task
[2022-10-29 16:00:44,949] {standard_task_runner.py:79} INFO - Running: ['***', 'tasks', 'run', 'get_files_denue', 'extract', 'scheduled__2022-09-01T00:00:00+00:00', '--job-id', '3', '--raw', '--subdir', 'DAGS_FOLDER/get_raw_files/get_files_denue.py', '--cfg-path', '/tmp/tmpcq98jp67', '--error-file', '/tmp/tmpl1ty1iju']
[2022-10-29 16:00:44,950] {standard_task_runner.py:80} INFO - Job 3: Subtask extract
[2022-10-29 16:00:45,072] {task_command.py:371} INFO - Running <TaskInstance: get_files_denue.extract scheduled__2022-09-01T00:00:00+00:00 [running]> on host 764803a942e2
[2022-10-29 16:00:45,115] {taskinstance.py:1591} INFO - Exporting the following env vars:
AIRFLOW_CTX_DAG_OWNER=Freakisimo
AIRFLOW_CTX_DAG_ID=get_files_denue
AIRFLOW_CTX_TASK_ID=extract
AIRFLOW_CTX_EXECUTION_DATE=2022-09-01T00:00:00+00:00
AIRFLOW_CTX_TRY_NUMBER=1
AIRFLOW_CTX_DAG_RUN_ID=scheduled__2022-09-01T00:00:00+00:00
[2022-10-29 16:00:45,783] {taskinstance.py:1909} ERROR - Task failed with exception
Traceback (most recent call last):
  File "/home/airflow/.local/lib/python3.7/site-packages/airflow/decorators/base.py", line 179, in execute
    return_value = super().execute(context)
  File "/home/airflow/.local/lib/python3.7/site-packages/airflow/operators/python.py", line 171, in execute
    return_value = self.execute_callable()
  File "/home/airflow/.local/lib/python3.7/site-packages/airflow/operators/python.py", line 189, in execute_callable
    return self.python_callable(*self.op_args, **self.op_kwargs)
  File "/opt/airflow/dags/get_raw_files/get_files_denue.py", line 28, in extract
    innertext='en formato csv'
  File "/opt/airflow/dags/utils/python_tools.py", line 35, in download_files
    driver = webdriver.Chrome()
  File "/home/airflow/.local/lib/python3.7/site-packages/selenium/webdriver/chrome/webdriver.py", line 72, in __init__
    service_log_path, service, keep_alive)
  File "/home/airflow/.local/lib/python3.7/site-packages/selenium/webdriver/chromium/webdriver.py", line 97, in __init__
    options=options)
  File "/home/airflow/.local/lib/python3.7/site-packages/selenium/webdriver/remote/webdriver.py", line 272, in __init__
    self.start_session(capabilities, browser_profile)
  File "/home/airflow/.local/lib/python3.7/site-packages/selenium/webdriver/remote/webdriver.py", line 364, in start_session
    response = self.execute(Command.NEW_SESSION, parameters)
  File "/home/airflow/.local/lib/python3.7/site-packages/selenium/webdriver/remote/webdriver.py", line 429, in execute
    self.error_handler.check_response(response)
  File "/home/airflow/.local/lib/python3.7/site-packages/selenium/webdriver/remote/errorhandler.py", line 243, in check_response
    raise exception_class(message, screen, stacktrace)
selenium.common.exceptions.WebDriverException: Message: unknown error: Chrome failed to start: crashed.
  (unknown error: DevToolsActivePort file doesn't exist)
  (The process started from chrome location /usr/bin/google-chrome is no longer running, so ChromeDriver is assuming that Chrome has crashed.)
Stacktrace:
#0 0x55b990d3d463 <unknown>
#1 0x55b990b018d8 <unknown>
#2 0x55b990b29b6a <unknown>
#3 0x55b990b24c05 <unknown>
#4 0x55b990b68802 <unknown>
#5 0x55b990b682af <unknown>
#6 0x55b990b60443 <unknown>
#7 0x55b990b313c5 <unknown>
#8 0x55b990b32531 <unknown>
#9 0x55b990d8fdce <unknown>
#10 0x55b990d93192 <unknown>
#11 0x55b990d7493e <unknown>
#12 0x55b990d94103 <unknown>
#13 0x55b990d67d85 <unknown>
#14 0x55b990db50a8 <unknown>
#15 0x55b990db5239 <unknown>
#16 0x55b990dd0492 <unknown>
#17 0x7f78550d8ea7 start_thread

[2022-10-29 16:00:45,789] {taskinstance.py:1420} INFO - Marking task as UP_FOR_RETRY. dag_id=get_files_denue, task_id=extract, execution_date=20220901T000000, start_date=20221029T160044, end_date=20221029T160045
[2022-10-29 16:00:45,797] {standard_task_runner.py:97} ERROR - Failed to execute job 3 for task extract (Message: unknown error: Chrome failed to start: crashed.
  (unknown error: DevToolsActivePort file doesn't exist)
  (The process started from chrome location /usr/bin/google-chrome is no longer running, so ChromeDriver is assuming that Chrome has crashed.)
Stacktrace:
#0 0x55b990d3d463 <unknown>
#1 0x55b990b018d8 <unknown>
#2 0x55b990b29b6a <unknown>
#3 0x55b990b24c05 <unknown>
#4 0x55b990b68802 <unknown>
#5 0x55b990b682af <unknown>
#6 0x55b990b60443 <unknown>
#7 0x55b990b313c5 <unknown>
#8 0x55b990b32531 <unknown>
#9 0x55b990d8fdce <unknown>
#10 0x55b990d93192 <unknown>
#11 0x55b990d7493e <unknown>
#12 0x55b990d94103 <unknown>
#13 0x55b990d67d85 <unknown>
#14 0x55b990db50a8 <unknown>
#15 0x55b990db5239 <unknown>
#16 0x55b990dd0492 <unknown>
#17 0x7f78550d8ea7 start_thread
; 206)
[2022-10-29 16:00:45,842] {local_task_job.py:156} INFO - Task exited with return code 1
[2022-10-29 16:00:45,957] {local_task_job.py:273} INFO - 0 downstream tasks scheduled from follow-on schedule check
[2022-10-29 16:14:02,922] {taskinstance.py:1179} INFO - Dependencies all met for <TaskInstance: get_files_denue.extract scheduled__2022-09-01T00:00:00+00:00 [queued]>
[2022-10-29 16:14:02,927] {taskinstance.py:1179} INFO - Dependencies all met for <TaskInstance: get_files_denue.extract scheduled__2022-09-01T00:00:00+00:00 [queued]>
[2022-10-29 16:14:02,927] {taskinstance.py:1376} INFO - 
--------------------------------------------------------------------------------
[2022-10-29 16:14:02,927] {taskinstance.py:1377} INFO - Starting attempt 1 of 6
[2022-10-29 16:14:02,927] {taskinstance.py:1378} INFO - 
--------------------------------------------------------------------------------
[2022-10-29 16:14:02,935] {taskinstance.py:1397} INFO - Executing <Task(_PythonDecoratedOperator): extract> on 2022-09-01 00:00:00+00:00
[2022-10-29 16:14:02,940] {standard_task_runner.py:52} INFO - Started process 245 to run task
[2022-10-29 16:14:02,941] {standard_task_runner.py:79} INFO - Running: ['***', 'tasks', 'run', 'get_files_denue', 'extract', 'scheduled__2022-09-01T00:00:00+00:00', '--job-id', '3', '--raw', '--subdir', 'DAGS_FOLDER/get_raw_files/get_files_denue.py', '--cfg-path', '/tmp/tmpgpe351dq', '--error-file', '/tmp/tmplvbh3rna']
[2022-10-29 16:14:02,942] {standard_task_runner.py:80} INFO - Job 3: Subtask extract
[2022-10-29 16:14:02,973] {task_command.py:371} INFO - Running <TaskInstance: get_files_denue.extract scheduled__2022-09-01T00:00:00+00:00 [running]> on host b547886b8bf1
[2022-10-29 16:14:03,120] {taskinstance.py:1591} INFO - Exporting the following env vars:
AIRFLOW_CTX_DAG_OWNER=Freakisimo
AIRFLOW_CTX_DAG_ID=get_files_denue
AIRFLOW_CTX_TASK_ID=extract
AIRFLOW_CTX_EXECUTION_DATE=2022-09-01T00:00:00+00:00
AIRFLOW_CTX_TRY_NUMBER=1
AIRFLOW_CTX_DAG_RUN_ID=scheduled__2022-09-01T00:00:00+00:00
[2022-10-29 16:14:03,128] {taskinstance.py:1909} ERROR - Task failed with exception
Traceback (most recent call last):
  File "/home/airflow/.local/lib/python3.7/site-packages/selenium/webdriver/common/service.py", line 76, in start
    creationflags=self.creationflags)
  File "/usr/local/lib/python3.7/subprocess.py", line 800, in __init__
    restore_signals, start_new_session)
  File "/usr/local/lib/python3.7/subprocess.py", line 1551, in _execute_child
    raise child_exception_type(errno_num, err_msg, err_filename)
PermissionError: [Errno 13] Permission denied: '/chromedriver/chromedriver'

During handling of the above exception, another exception occurred:

Traceback (most recent call last):
  File "/home/airflow/.local/lib/python3.7/site-packages/airflow/decorators/base.py", line 179, in execute
    return_value = super().execute(context)
  File "/home/airflow/.local/lib/python3.7/site-packages/airflow/operators/python.py", line 171, in execute
    return_value = self.execute_callable()
  File "/home/airflow/.local/lib/python3.7/site-packages/airflow/operators/python.py", line 189, in execute_callable
    return self.python_callable(*self.op_args, **self.op_kwargs)
  File "/opt/airflow/dags/get_raw_files/get_files_denue.py", line 28, in extract
    innertext='en formato csv'
  File "/opt/airflow/dags/utils/python_tools.py", line 35, in download_files
    driver = webdriver.Chrome(executable_path='/chromedriver/chromedriver')
  File "/home/airflow/.local/lib/python3.7/site-packages/selenium/webdriver/chrome/webdriver.py", line 72, in __init__
    service_log_path, service, keep_alive)
  File "/home/airflow/.local/lib/python3.7/site-packages/selenium/webdriver/chromium/webdriver.py", line 89, in __init__
    self.service.start()
  File "/home/airflow/.local/lib/python3.7/site-packages/selenium/webdriver/common/service.py", line 88, in start
    os.path.basename(self.path), self.start_error_message)
selenium.common.exceptions.WebDriverException: Message: 'chromedriver' executable may have wrong permissions. Please see https://chromedriver.chromium.org/home

[2022-10-29 16:14:03,134] {taskinstance.py:1420} INFO - Marking task as UP_FOR_RETRY. dag_id=get_files_denue, task_id=extract, execution_date=20220901T000000, start_date=20221029T161402, end_date=20221029T161403
[2022-10-29 16:14:03,141] {standard_task_runner.py:97} ERROR - Failed to execute job 3 for task extract (Message: 'chromedriver' executable may have wrong permissions. Please see https://chromedriver.chromium.org/home
; 245)
[2022-10-29 16:14:03,153] {local_task_job.py:156} INFO - Task exited with return code 1
[2022-10-29 16:14:03,181] {local_task_job.py:273} INFO - 0 downstream tasks scheduled from follow-on schedule check
[2022-10-29 16:23:37,696] {taskinstance.py:1179} INFO - Dependencies all met for <TaskInstance: get_files_denue.extract scheduled__2022-09-01T00:00:00+00:00 [queued]>
[2022-10-29 16:23:37,701] {taskinstance.py:1179} INFO - Dependencies all met for <TaskInstance: get_files_denue.extract scheduled__2022-09-01T00:00:00+00:00 [queued]>
[2022-10-29 16:23:37,701] {taskinstance.py:1376} INFO - 
--------------------------------------------------------------------------------
[2022-10-29 16:23:37,701] {taskinstance.py:1377} INFO - Starting attempt 1 of 6
[2022-10-29 16:23:37,702] {taskinstance.py:1378} INFO - 
--------------------------------------------------------------------------------
[2022-10-29 16:23:37,710] {taskinstance.py:1397} INFO - Executing <Task(_PythonDecoratedOperator): extract> on 2022-09-01 00:00:00+00:00
[2022-10-29 16:23:37,714] {standard_task_runner.py:52} INFO - Started process 197 to run task
[2022-10-29 16:23:37,716] {standard_task_runner.py:79} INFO - Running: ['***', 'tasks', 'run', 'get_files_denue', 'extract', 'scheduled__2022-09-01T00:00:00+00:00', '--job-id', '3', '--raw', '--subdir', 'DAGS_FOLDER/get_raw_files/get_files_denue.py', '--cfg-path', '/tmp/tmp7nonq1lo', '--error-file', '/tmp/tmpoo4afh6z']
[2022-10-29 16:23:37,717] {standard_task_runner.py:80} INFO - Job 3: Subtask extract
[2022-10-29 16:23:37,844] {task_command.py:371} INFO - Running <TaskInstance: get_files_denue.extract scheduled__2022-09-01T00:00:00+00:00 [running]> on host 0e9bebf0afc5
[2022-10-29 16:23:37,888] {taskinstance.py:1591} INFO - Exporting the following env vars:
AIRFLOW_CTX_DAG_OWNER=Freakisimo
AIRFLOW_CTX_DAG_ID=get_files_denue
AIRFLOW_CTX_TASK_ID=extract
AIRFLOW_CTX_EXECUTION_DATE=2022-09-01T00:00:00+00:00
AIRFLOW_CTX_TRY_NUMBER=1
AIRFLOW_CTX_DAG_RUN_ID=scheduled__2022-09-01T00:00:00+00:00
[2022-10-29 16:23:37,896] {taskinstance.py:1909} ERROR - Task failed with exception
Traceback (most recent call last):
  File "/home/airflow/.local/lib/python3.7/site-packages/selenium/webdriver/common/service.py", line 76, in start
    creationflags=self.creationflags)
  File "/usr/local/lib/python3.7/subprocess.py", line 800, in __init__
    restore_signals, start_new_session)
  File "/usr/local/lib/python3.7/subprocess.py", line 1551, in _execute_child
    raise child_exception_type(errno_num, err_msg, err_filename)
PermissionError: [Errno 13] Permission denied: '/chromedriver/chromedriver'

During handling of the above exception, another exception occurred:

Traceback (most recent call last):
  File "/home/airflow/.local/lib/python3.7/site-packages/airflow/decorators/base.py", line 179, in execute
    return_value = super().execute(context)
  File "/home/airflow/.local/lib/python3.7/site-packages/airflow/operators/python.py", line 171, in execute
    return_value = self.execute_callable()
  File "/home/airflow/.local/lib/python3.7/site-packages/airflow/operators/python.py", line 189, in execute_callable
    return self.python_callable(*self.op_args, **self.op_kwargs)
  File "/opt/airflow/dags/get_raw_files/get_files_denue.py", line 28, in extract
    innertext='en formato csv'
  File "/opt/airflow/dags/utils/python_tools.py", line 35, in download_files
    driver = webdriver.Chrome(executable_path='/chromedriver/chromedriver')
  File "/home/airflow/.local/lib/python3.7/site-packages/selenium/webdriver/chrome/webdriver.py", line 72, in __init__
    service_log_path, service, keep_alive)
  File "/home/airflow/.local/lib/python3.7/site-packages/selenium/webdriver/chromium/webdriver.py", line 89, in __init__
    self.service.start()
  File "/home/airflow/.local/lib/python3.7/site-packages/selenium/webdriver/common/service.py", line 88, in start
    os.path.basename(self.path), self.start_error_message)
selenium.common.exceptions.WebDriverException: Message: 'chromedriver' executable may have wrong permissions. Please see https://chromedriver.chromium.org/home

[2022-10-29 16:23:37,902] {taskinstance.py:1420} INFO - Marking task as UP_FOR_RETRY. dag_id=get_files_denue, task_id=extract, execution_date=20220901T000000, start_date=20221029T162337, end_date=20221029T162337
[2022-10-29 16:23:37,908] {standard_task_runner.py:97} ERROR - Failed to execute job 3 for task extract (Message: 'chromedriver' executable may have wrong permissions. Please see https://chromedriver.chromium.org/home
; 197)
[2022-10-29 16:23:37,927] {local_task_job.py:156} INFO - Task exited with return code 1
[2022-10-29 16:23:38,051] {local_task_job.py:273} INFO - 0 downstream tasks scheduled from follow-on schedule check
[2022-10-29 16:32:18,551] {taskinstance.py:1179} INFO - Dependencies all met for <TaskInstance: get_files_denue.extract scheduled__2022-09-01T00:00:00+00:00 [queued]>
[2022-10-29 16:32:18,556] {taskinstance.py:1179} INFO - Dependencies all met for <TaskInstance: get_files_denue.extract scheduled__2022-09-01T00:00:00+00:00 [queued]>
[2022-10-29 16:32:18,557] {taskinstance.py:1376} INFO - 
--------------------------------------------------------------------------------
[2022-10-29 16:32:18,557] {taskinstance.py:1377} INFO - Starting attempt 1 of 6
[2022-10-29 16:32:18,557] {taskinstance.py:1378} INFO - 
--------------------------------------------------------------------------------
[2022-10-29 16:32:18,564] {taskinstance.py:1397} INFO - Executing <Task(_PythonDecoratedOperator): extract> on 2022-09-01 00:00:00+00:00
[2022-10-29 16:32:18,569] {standard_task_runner.py:52} INFO - Started process 245 to run task
[2022-10-29 16:32:18,571] {standard_task_runner.py:79} INFO - Running: ['***', 'tasks', 'run', 'get_files_denue', 'extract', 'scheduled__2022-09-01T00:00:00+00:00', '--job-id', '3', '--raw', '--subdir', 'DAGS_FOLDER/get_raw_files/get_files_denue.py', '--cfg-path', '/tmp/tmpl8vtfbld', '--error-file', '/tmp/tmpqh2_o1jl']
[2022-10-29 16:32:18,572] {standard_task_runner.py:80} INFO - Job 3: Subtask extract
[2022-10-29 16:32:18,702] {task_command.py:371} INFO - Running <TaskInstance: get_files_denue.extract scheduled__2022-09-01T00:00:00+00:00 [running]> on host 5e8bab7a3cdc
[2022-10-29 16:32:18,746] {taskinstance.py:1591} INFO - Exporting the following env vars:
AIRFLOW_CTX_DAG_OWNER=Freakisimo
AIRFLOW_CTX_DAG_ID=get_files_denue
AIRFLOW_CTX_TASK_ID=extract
AIRFLOW_CTX_EXECUTION_DATE=2022-09-01T00:00:00+00:00
AIRFLOW_CTX_TRY_NUMBER=1
AIRFLOW_CTX_DAG_RUN_ID=scheduled__2022-09-01T00:00:00+00:00
[2022-10-29 16:32:18,747] {taskinstance.py:1909} ERROR - Task failed with exception
Traceback (most recent call last):
  File "/home/airflow/.local/lib/python3.7/site-packages/airflow/decorators/base.py", line 179, in execute
    return_value = super().execute(context)
  File "/home/airflow/.local/lib/python3.7/site-packages/airflow/operators/python.py", line 171, in execute
    return_value = self.execute_callable()
  File "/home/airflow/.local/lib/python3.7/site-packages/airflow/operators/python.py", line 189, in execute_callable
    return self.python_callable(*self.op_args, **self.op_kwargs)
  File "/opt/airflow/dags/get_raw_files/get_files_denue.py", line 28, in extract
    innertext='en formato csv'
  File "/opt/airflow/dags/utils/python_tools.py", line 35, in download_files
    os.chmod('/chromedriver/chromedriver', 0o755)
PermissionError: [Errno 1] Operation not permitted: '/chromedriver/chromedriver'
[2022-10-29 16:32:18,751] {taskinstance.py:1420} INFO - Marking task as UP_FOR_RETRY. dag_id=get_files_denue, task_id=extract, execution_date=20220901T000000, start_date=20221029T163218, end_date=20221029T163218
[2022-10-29 16:32:18,757] {standard_task_runner.py:97} ERROR - Failed to execute job 3 for task extract ([Errno 1] Operation not permitted: '/chromedriver/chromedriver'; 245)
[2022-10-29 16:32:18,782] {local_task_job.py:156} INFO - Task exited with return code 1
[2022-10-29 16:32:18,905] {local_task_job.py:273} INFO - 0 downstream tasks scheduled from follow-on schedule check
[2022-10-29 16:47:28,262] {taskinstance.py:1179} INFO - Dependencies all met for <TaskInstance: get_files_denue.extract scheduled__2022-09-01T00:00:00+00:00 [queued]>
[2022-10-29 16:47:28,267] {taskinstance.py:1179} INFO - Dependencies all met for <TaskInstance: get_files_denue.extract scheduled__2022-09-01T00:00:00+00:00 [queued]>
[2022-10-29 16:47:28,267] {taskinstance.py:1376} INFO - 
--------------------------------------------------------------------------------
[2022-10-29 16:47:28,267] {taskinstance.py:1377} INFO - Starting attempt 1 of 6
[2022-10-29 16:47:28,268] {taskinstance.py:1378} INFO - 
--------------------------------------------------------------------------------
[2022-10-29 16:47:28,275] {taskinstance.py:1397} INFO - Executing <Task(_PythonDecoratedOperator): extract> on 2022-09-01 00:00:00+00:00
[2022-10-29 16:47:28,280] {standard_task_runner.py:52} INFO - Started process 206 to run task
[2022-10-29 16:47:28,282] {standard_task_runner.py:79} INFO - Running: ['***', 'tasks', 'run', 'get_files_denue', 'extract', 'scheduled__2022-09-01T00:00:00+00:00', '--job-id', '3', '--raw', '--subdir', 'DAGS_FOLDER/get_raw_files/get_files_denue.py', '--cfg-path', '/tmp/tmp6r9446p_', '--error-file', '/tmp/tmpzmja6oui']
[2022-10-29 16:47:28,282] {standard_task_runner.py:80} INFO - Job 3: Subtask extract
[2022-10-29 16:47:28,407] {task_command.py:371} INFO - Running <TaskInstance: get_files_denue.extract scheduled__2022-09-01T00:00:00+00:00 [running]> on host c039490bd884
[2022-10-29 16:47:28,452] {taskinstance.py:1591} INFO - Exporting the following env vars:
AIRFLOW_CTX_DAG_OWNER=Freakisimo
AIRFLOW_CTX_DAG_ID=get_files_denue
AIRFLOW_CTX_TASK_ID=extract
AIRFLOW_CTX_EXECUTION_DATE=2022-09-01T00:00:00+00:00
AIRFLOW_CTX_TRY_NUMBER=1
AIRFLOW_CTX_DAG_RUN_ID=scheduled__2022-09-01T00:00:00+00:00
[2022-10-29 16:47:28,461] {taskinstance.py:1909} ERROR - Task failed with exception
Traceback (most recent call last):
  File "/home/airflow/.local/lib/python3.7/site-packages/selenium/webdriver/common/service.py", line 76, in start
    creationflags=self.creationflags)
  File "/usr/local/lib/python3.7/subprocess.py", line 800, in __init__
    restore_signals, start_new_session)
  File "/usr/local/lib/python3.7/subprocess.py", line 1551, in _execute_child
    raise child_exception_type(errno_num, err_msg, err_filename)
PermissionError: [Errno 13] Permission denied: '/chromedriver/chromedriver'

During handling of the above exception, another exception occurred:

Traceback (most recent call last):
  File "/home/airflow/.local/lib/python3.7/site-packages/airflow/decorators/base.py", line 179, in execute
    return_value = super().execute(context)
  File "/home/airflow/.local/lib/python3.7/site-packages/airflow/operators/python.py", line 171, in execute
    return_value = self.execute_callable()
  File "/home/airflow/.local/lib/python3.7/site-packages/airflow/operators/python.py", line 189, in execute_callable
    return self.python_callable(*self.op_args, **self.op_kwargs)
  File "/opt/airflow/dags/get_raw_files/get_files_denue.py", line 28, in extract
    innertext='en formato csv'
  File "/opt/airflow/dags/utils/python_tools.py", line 35, in download_files
    driver = webdriver.Chrome(executable_path='/chromedriver/chromedriver')
  File "/home/airflow/.local/lib/python3.7/site-packages/selenium/webdriver/chrome/webdriver.py", line 72, in __init__
    service_log_path, service, keep_alive)
  File "/home/airflow/.local/lib/python3.7/site-packages/selenium/webdriver/chromium/webdriver.py", line 89, in __init__
    self.service.start()
  File "/home/airflow/.local/lib/python3.7/site-packages/selenium/webdriver/common/service.py", line 88, in start
    os.path.basename(self.path), self.start_error_message)
selenium.common.exceptions.WebDriverException: Message: 'chromedriver' executable may have wrong permissions. Please see https://chromedriver.chromium.org/home

[2022-10-29 16:47:28,466] {taskinstance.py:1420} INFO - Marking task as UP_FOR_RETRY. dag_id=get_files_denue, task_id=extract, execution_date=20220901T000000, start_date=20221029T164728, end_date=20221029T164728
[2022-10-29 16:47:28,473] {standard_task_runner.py:97} ERROR - Failed to execute job 3 for task extract (Message: 'chromedriver' executable may have wrong permissions. Please see https://chromedriver.chromium.org/home
; 206)
[2022-10-29 16:47:28,493] {local_task_job.py:156} INFO - Task exited with return code 1
[2022-10-29 16:47:28,607] {local_task_job.py:273} INFO - 0 downstream tasks scheduled from follow-on schedule check
[2022-10-29 16:54:39,642] {taskinstance.py:1179} INFO - Dependencies all met for <TaskInstance: get_files_denue.extract scheduled__2022-09-01T00:00:00+00:00 [queued]>
[2022-10-29 16:54:39,647] {taskinstance.py:1179} INFO - Dependencies all met for <TaskInstance: get_files_denue.extract scheduled__2022-09-01T00:00:00+00:00 [queued]>
[2022-10-29 16:54:39,647] {taskinstance.py:1376} INFO - 
--------------------------------------------------------------------------------
[2022-10-29 16:54:39,647] {taskinstance.py:1377} INFO - Starting attempt 1 of 6
[2022-10-29 16:54:39,648] {taskinstance.py:1378} INFO - 
--------------------------------------------------------------------------------
[2022-10-29 16:54:39,656] {taskinstance.py:1397} INFO - Executing <Task(_PythonDecoratedOperator): extract> on 2022-09-01 00:00:00+00:00
[2022-10-29 16:54:39,660] {standard_task_runner.py:52} INFO - Started process 204 to run task
[2022-10-29 16:54:39,662] {standard_task_runner.py:79} INFO - Running: ['***', 'tasks', 'run', 'get_files_denue', 'extract', 'scheduled__2022-09-01T00:00:00+00:00', '--job-id', '3', '--raw', '--subdir', 'DAGS_FOLDER/get_raw_files/get_files_denue.py', '--cfg-path', '/tmp/tmpvshgnsrs', '--error-file', '/tmp/tmp66bom0v1']
[2022-10-29 16:54:39,663] {standard_task_runner.py:80} INFO - Job 3: Subtask extract
[2022-10-29 16:54:39,803] {task_command.py:371} INFO - Running <TaskInstance: get_files_denue.extract scheduled__2022-09-01T00:00:00+00:00 [running]> on host 167153ec7ac7
[2022-10-29 16:54:39,851] {taskinstance.py:1591} INFO - Exporting the following env vars:
AIRFLOW_CTX_DAG_OWNER=Freakisimo
AIRFLOW_CTX_DAG_ID=get_files_denue
AIRFLOW_CTX_TASK_ID=extract
AIRFLOW_CTX_EXECUTION_DATE=2022-09-01T00:00:00+00:00
AIRFLOW_CTX_TRY_NUMBER=1
AIRFLOW_CTX_DAG_RUN_ID=scheduled__2022-09-01T00:00:00+00:00
[2022-10-29 16:54:39,861] {taskinstance.py:1909} ERROR - Task failed with exception
Traceback (most recent call last):
  File "/home/airflow/.local/lib/python3.7/site-packages/selenium/webdriver/common/service.py", line 76, in start
    creationflags=self.creationflags)
  File "/usr/local/lib/python3.7/subprocess.py", line 800, in __init__
    restore_signals, start_new_session)
  File "/usr/local/lib/python3.7/subprocess.py", line 1551, in _execute_child
    raise child_exception_type(errno_num, err_msg, err_filename)
PermissionError: [Errno 13] Permission denied: '/chromedriver/chromedriver'

During handling of the above exception, another exception occurred:

Traceback (most recent call last):
  File "/home/airflow/.local/lib/python3.7/site-packages/airflow/decorators/base.py", line 179, in execute
    return_value = super().execute(context)
  File "/home/airflow/.local/lib/python3.7/site-packages/airflow/operators/python.py", line 171, in execute
    return_value = self.execute_callable()
  File "/home/airflow/.local/lib/python3.7/site-packages/airflow/operators/python.py", line 189, in execute_callable
    return self.python_callable(*self.op_args, **self.op_kwargs)
  File "/opt/airflow/dags/get_raw_files/get_files_denue.py", line 28, in extract
    innertext='en formato csv'
  File "/opt/airflow/dags/utils/python_tools.py", line 39, in download_files
    driver = webdriver.Chrome(executable_path='/chromedriver/chromedriver', options=chrome_options)
  File "/home/airflow/.local/lib/python3.7/site-packages/selenium/webdriver/chrome/webdriver.py", line 72, in __init__
    service_log_path, service, keep_alive)
  File "/home/airflow/.local/lib/python3.7/site-packages/selenium/webdriver/chromium/webdriver.py", line 89, in __init__
    self.service.start()
  File "/home/airflow/.local/lib/python3.7/site-packages/selenium/webdriver/common/service.py", line 88, in start
    os.path.basename(self.path), self.start_error_message)
selenium.common.exceptions.WebDriverException: Message: 'chromedriver' executable may have wrong permissions. Please see https://chromedriver.chromium.org/home

[2022-10-29 16:54:39,868] {taskinstance.py:1420} INFO - Marking task as UP_FOR_RETRY. dag_id=get_files_denue, task_id=extract, execution_date=20220901T000000, start_date=20221029T165439, end_date=20221029T165439
[2022-10-29 16:54:39,875] {standard_task_runner.py:97} ERROR - Failed to execute job 3 for task extract (Message: 'chromedriver' executable may have wrong permissions. Please see https://chromedriver.chromium.org/home
; 204)
[2022-10-29 16:54:39,913] {local_task_job.py:156} INFO - Task exited with return code 1
[2022-10-29 16:54:40,033] {local_task_job.py:273} INFO - 0 downstream tasks scheduled from follow-on schedule check
[2022-10-29 19:15:02,872] {taskinstance.py:1179} INFO - Dependencies all met for <TaskInstance: get_files_denue.extract scheduled__2022-09-01T00:00:00+00:00 [queued]>
[2022-10-29 19:15:02,878] {taskinstance.py:1179} INFO - Dependencies all met for <TaskInstance: get_files_denue.extract scheduled__2022-09-01T00:00:00+00:00 [queued]>
[2022-10-29 19:15:02,878] {taskinstance.py:1376} INFO - 
--------------------------------------------------------------------------------
[2022-10-29 19:15:02,878] {taskinstance.py:1377} INFO - Starting attempt 1 of 6
[2022-10-29 19:15:02,878] {taskinstance.py:1378} INFO - 
--------------------------------------------------------------------------------
[2022-10-29 19:15:02,886] {taskinstance.py:1397} INFO - Executing <Task(_PythonDecoratedOperator): extract> on 2022-09-01 00:00:00+00:00
[2022-10-29 19:15:02,891] {standard_task_runner.py:52} INFO - Started process 392 to run task
[2022-10-29 19:15:02,892] {standard_task_runner.py:79} INFO - Running: ['***', 'tasks', 'run', 'get_files_denue', 'extract', 'scheduled__2022-09-01T00:00:00+00:00', '--job-id', '3', '--raw', '--subdir', 'DAGS_FOLDER/get_raw_files/get_files_denue.py', '--cfg-path', '/tmp/tmpk03fuflo', '--error-file', '/tmp/tmpe8exu1wc']
[2022-10-29 19:15:02,893] {standard_task_runner.py:80} INFO - Job 3: Subtask extract
[2022-10-29 19:15:02,927] {task_command.py:371} INFO - Running <TaskInstance: get_files_denue.extract scheduled__2022-09-01T00:00:00+00:00 [running]> on host 4cf715aa1215
[2022-10-29 19:15:03,069] {taskinstance.py:1591} INFO - Exporting the following env vars:
AIRFLOW_CTX_DAG_OWNER=Freakisimo
AIRFLOW_CTX_DAG_ID=get_files_denue
AIRFLOW_CTX_TASK_ID=extract
AIRFLOW_CTX_EXECUTION_DATE=2022-09-01T00:00:00+00:00
AIRFLOW_CTX_TRY_NUMBER=1
AIRFLOW_CTX_DAG_RUN_ID=scheduled__2022-09-01T00:00:00+00:00
[2022-10-29 19:15:03,079] {taskinstance.py:1909} ERROR - Task failed with exception
Traceback (most recent call last):
  File "/home/airflow/.local/lib/python3.7/site-packages/selenium/webdriver/common/service.py", line 76, in start
    creationflags=self.creationflags)
  File "/usr/local/lib/python3.7/subprocess.py", line 800, in __init__
    restore_signals, start_new_session)
  File "/usr/local/lib/python3.7/subprocess.py", line 1551, in _execute_child
    raise child_exception_type(errno_num, err_msg, err_filename)
FileNotFoundError: [Errno 2] No such file or directory: '/chromedriver/chromedriver': '/chromedriver/chromedriver'

During handling of the above exception, another exception occurred:

Traceback (most recent call last):
  File "/home/airflow/.local/lib/python3.7/site-packages/airflow/decorators/base.py", line 179, in execute
    return_value = super().execute(context)
  File "/home/airflow/.local/lib/python3.7/site-packages/airflow/operators/python.py", line 171, in execute
    return_value = self.execute_callable()
  File "/home/airflow/.local/lib/python3.7/site-packages/airflow/operators/python.py", line 189, in execute_callable
    return self.python_callable(*self.op_args, **self.op_kwargs)
  File "/opt/airflow/dags/get_raw_files/get_files_denue.py", line 28, in extract
    innertext='en formato csv'
  File "/opt/airflow/dags/utils/python_tools.py", line 39, in download_files
    driver = webdriver.Chrome(executable_path='/chromedriver/chromedriver', options=chrome_options)
  File "/home/airflow/.local/lib/python3.7/site-packages/selenium/webdriver/chrome/webdriver.py", line 72, in __init__
    service_log_path, service, keep_alive)
  File "/home/airflow/.local/lib/python3.7/site-packages/selenium/webdriver/chromium/webdriver.py", line 89, in __init__
    self.service.start()
  File "/home/airflow/.local/lib/python3.7/site-packages/selenium/webdriver/common/service.py", line 83, in start
    os.path.basename(self.path), self.start_error_message)
selenium.common.exceptions.WebDriverException: Message: 'chromedriver' executable needs to be in PATH. Please see https://chromedriver.chromium.org/home

[2022-10-29 19:15:03,085] {taskinstance.py:1420} INFO - Marking task as UP_FOR_RETRY. dag_id=get_files_denue, task_id=extract, execution_date=20220901T000000, start_date=20221029T191502, end_date=20221029T191503
[2022-10-29 19:15:03,091] {standard_task_runner.py:97} ERROR - Failed to execute job 3 for task extract (Message: 'chromedriver' executable needs to be in PATH. Please see https://chromedriver.chromium.org/home
; 392)
[2022-10-29 19:15:03,104] {local_task_job.py:156} INFO - Task exited with return code 1
[2022-10-29 19:15:03,133] {local_task_job.py:273} INFO - 0 downstream tasks scheduled from follow-on schedule check
